Workbook
Name Z_3E12C599_4482_4A62_878B_030CF5DA4B04_.wvu.PrintTitles: Guardias!#REF!
Name Z_3E12C599_4482_4A62_878B_030CF5DA4B04_.wvu.PrintTitles: Asistencia!$1:$19
Name DÍA: Tablas!$B$3:$B$9
Name EdoCivil: Tablas!$I$3:$I$8
Name CVE: Tablas!$A$2:$A$9

Sheet Tablas
A1: | | B1: DÍA | C1: RESPONSABLE DEL DÍA | D1: COORDINADORA | G1: Edad | I1: Clave | J1: Grupo
A2: B | B2: BAJA | C2: - | D2: - | G2: de | H2: a
A3: L | B3: LUNES | C3: Hernández Martínez Miguel | D3: Velazco Arreola María Rufina | G3: 45 | H3: 120 | I3: CG | J3: Casad@s Grandes
A4: Ma | B4: MARTES | C4: Mauricio Olvera Jesús | D4: Sánchez Ramos María Emilia | G4: 30 | H4: =G3-1 -> 44 | I4: CM | J4: Casad@s Medianos
A5: Mi | B5: MIÉRCOLES | C5: Nava Cárdenas Guillermo | D5: Silva Morales Martha Elva | G5: 18 | H5: =G4-1 -> 29 | I5: CC | J5: Casad@s Chicos
A6: J | B6: JUEVES | C6: Gomez Quintero Jesus | D6: Aguayo Gómez Ramona | G6: =G5 -> 18 | H6: =H3 -> 120 | I6: SO | J6: Sol@s
A7: V | B7: VIERNES | C7: Chávez Ubaldo Natanael | D7: Herrera Lozano Rebeca | G7: 14 | H7: =H3 -> 120 | I7: JU | J7: Juventud (Jóvenes y Señoritas) | L7: .
A8: S | B8: SÁBADO | C8: Luna Vázquez Bolívar | D8: Téllez Sara | G8: 0 | H8: =G7-1 -> 13 | I8: NI | J8: Niñez (Niños y Niñas)
A9: D | B9: DOMINGO | C9: Ramírez Ornelas Jesús | D9: Carrillo Herrera Rebeca Arelí

Sheet Informe
A1: INFORME DE ACTIVIDADES DE LA IGLESIA: GRUPO DE OBREROS H.P.
A3: Anterior | B3: 424 | H3: CG | I3: =COUNTIFS('Lista General'!$D$4:$D$723,LEFT(I$5,1),'Lista General'!$E$4:$E$723,$H3) -> 43 | J3: =COUNTIFS('Lista General'!$D:$D,LEFT(J$5,1),'Lista General'!$E:$E,$H3) -> 49
A4: FELIGRESÍA | D4: ASISTENCIA | G4: CENSO GENERAL | M4: MOVIMIENTOS
A5: Activos | B5: =B3+N11-P11 -> 389 | D5: Dominical | G5: Grupo | H5: Clave | I5: Mujeres | J5: Hombres | K5: Total | M5: Altas | O5: Bajas
A6: Retiro Temporal | D6: Serv. Dom. | G6: Casad@s Grandes | H6: CG | I6: 56 | J6: 52 | K6: =SUM(I6:J6) -> 108 | M6: Bautismos | O6: Traslados | P6: 35
A7: Registro General | D7: Serv. Jue. | G7: Casad@s Medianos | H7: CM | I7: 38 | J7: 26 | K7: =SUM(I7:J7) -> 64 | M7: Recibidos por Carta | N7: 2 | O7: Obra Entregada
A8: Miembro en Archivo | D8: Ora. 5 am | G8: Casad@s Chicos | H8: CC | I8: 11 | J8: 13 | K8: =SUM(I8:J8) -> 24 | M8: Recibidos por Testimonio | O8: Defunciones | P8: 2
A9: Total (Recuento Oficial) | D9: Ora. 9 am | G9: Sol@s | H9: SO | I9: 80 | J9: 16 | K9: =SUM(I9:J9) -> 96 | M9: Restauraciones | O9: Apostasía / Herejía
D10: Ora. 6 pm | G10: Juventud | H10: JU | I10: 50 | J10: 47 | K10: =SUM(I10:J10) -> 97 | M10: Nacimientos
A11: OFICIOS SAGRADOS | D11: Total | E11: =SUM(E5:E10) -> 0 | G11: Total | I11: =SUM(I6:I10) -> 235 | J11: =SUM(J6:J10) -> 154 | K11: =SUM(K6:K10) -> 389 | M11: Total | N11: =SUM(N6:N10) -> 2 | P11: =SUM(P6:P10) -> 37
A12: Matrimonios | B12: 1 | G12: Niñez | H12: NI | I12: =COUNTIFS('Lista General'!$D:$D,LEFT(I$5,1),'Lista General'!$E:$E,$H12) -> 0 | J12: =COUNTIFS('Lista General'!$D:$D,LEFT(J$5,1),'Lista General'!$E:$E,$H12) -> 0 | K12: =SUM(I12:J12) -> 0
A13: Espirituales | B13: 2 | G13: Gran Total | I13: =SUM(I11:I12) -> 235 | J13: =SUM(J11:J12) -> 154 | K13: =SUM(K11:K12) -> 389
A14: Presentación de Niños
A15: Total | B15: =SUM(B12:B14) -> 3
G16: ="Hnas.: "&SUM(G17:G23) -> Hnas.: 247 | H16: =SUM(G17:G23,I17:I23) -> 386 | I16: ="Hnos.: "&SUM(I17:I23) -> Hnos.: 139
A17: OTROS | G17: 28 | H17: lun | I17: 27
A18: Divorcios | G18: 36 | H18: mar | I18: 18
A19: Carta de Libertad | G19: 24 | H19: mie | I19: 16
A20: Total | B20: =SUM(B18:B19) -> 0 | G20: 31 | H20: jue | I20: 26
G21: 31 | H21: vie | I21: 20
G22: 61 | H22: sab | I22: 32
G23: 36 | H23: dom

Sheet Lista General
C1: ="Total: "&SUBTOTAL(3,$C$4:$C$723) -> Total: 354
A3: No. | B3: Llave | C3: N O M B R E | D3: G | F3: DIA | G3: CARTA | H3: REG. | I3: F. NAC. | J3: EDAD | K3: TEL. | L3: DIRECCION | M3: Fecha ingreso | N3: OBS.
A4: =IF(D4="","",COUNTA($D$4:$D4)) -> 1 | B4: =IF(C4="","",D4&F4&COUNTIFS($D$4:D4,D4,$F$4:F4,F4)) -> HS1 | C4: Abarca Chavez Rubén Salvador | D4: H | E4: JU | F4: S | G4: SÍ | H4: SÍ | I4: 37481 | J4: =IF(C4="","",DATEDIF(I4,TODAY(),"Y")) -> 23 | K4: 3326587210 | L4: Santiago Guzman 1314, Beatriz Hernandez | M4: 43468 | N4: 4 jovenes EHP Josue Coronado Hernandez
A5: =IF(D5="","",COUNTA($D$4:$D5)) -> 2 | B5: =IF(C5="","",D5&F5&COUNTIFS($D$4:D5,D5,$F$4:F5,F5)) -> HV1 | C5: Acevedo Aguilar Ariel | D5: H | E5: SO | F5: V | H5: SÍ | I5: 38995 | J5: =IF(C5="","",DATEDIF(I5,TODAY(),"Y")) -> 19 | K5: 3319417420 | L5: Geografos 617 Lagos de Oriente | M5: 45339 | N5: 1 Solos EHP Jose Sanchez Magaña
A6: =IF(D6="","",COUNTA($D$4:$D6)) -> 3 | B6: =IF(C6="","",D6&F6&COUNTIFS($D$4:D6,D6,$F$4:F6,F6)) -> HL1 | C6: Acevedo Lopez Jairo de Jesus | D6: H | E6: CG | F6: L | H6: SÍ | I6: 20188 | J6: =IF(C6="","",DATEDIF(I6,TODAY(),"Y")) -> 71 | K6: 3322199062 | L6: Presa Oviachic 790, San Joaquin | M6: 43434 | N6: 12 Casados, EHP Carlos Ramos Castillon
A7: =IF(D7="","",COUNTA($D$4:$D7)) -> 4 | B7: =IF(C7="","",D7&F7&COUNTIFS($D$4:D7,D7,$F$4:F7,F7)) -> MB1 | C7: Acevedo Vega Samla Jaanai | D7: M | E7: JU | F7: B | G7: SÍ | H7: SÍ | I7: 37713 | J7: =IF(C7="","",DATEDIF(I7,TODAY(),"Y")) -> 23 | K7: 3316716256 | L7: Esteban Alatorre,3317,Hermosa Provincia | M7: 39264
A8: =IF(D8="","",COUNTA($D$4:$D8)) -> 5 | B8: =IF(C8="","",D8&F8&COUNTIFS($D$4:D8,D8,$F$4:F8,F8)) -> MV1 | C8: Acosta Navarro Perla Damacia | D8: M | E8: CM | F8: V | H8: SÍ | I8: 28477 | J8: =IF(C8="","",DATEDIF(I8,TODAY(),"Y")) -> 48 | K8: 33.1236.8872 | L8: Demóstenes 405, Lagos De Oriente | M8: 42690 | N8: 10° Casadas, Hna. Drucila Almaguer
A9: =IF(D9="","",COUNTA($D$4:$D9)) -> 6 | B9: =IF(C9="","",D9&F9&COUNTIFS($D$4:D9,D9,$F$4:F9,F9)) -> MB2 | C9: Acuña Silverio Yenni Samai | D9: M | E9: JU | F9: B | G9: SÍ | H9: SÍ | I9: 38541 | J9: =IF(C9="","",DATEDIF(I9,TODAY(),"Y")) -> 20 | K9: 3325006442 | L9: Esteban Alatorre 3349, Hermosa Provincia | M9: 44643 | N9: 1° señoritas, EHP Elizabeth Estrada
A10: =IF(D10="","",COUNTA($D$4:$D10)) -> 7 | B10: =IF(C10="","",D10&F10&COUNTIFS($D$4:D10,D10,$F$4:F10,F10)) -> MJ1 | C10: Aguayo Bueno Amparo | D10: M | E10: SO | F10: J | G10: SÍ | H10: SÍ | I10: 18829 | J10: =IF(C10="","",DATEDIF(I10,TODAY(),"Y")) -> 74 | K10: 3310421508 | L10: Telegrafistas, 3566, Hermosa Provincia | N10: 6 Solas EHP María Elena Reyes vda de Acevedo
A11: =IF(D11="","",COUNTA($D$4:$D11)) -> 8 | B11: =IF(C11="","",D11&F11&COUNTIFS($D$4:D11,D11,$F$4:F11,F11)) -> MJ2 | C11: Aguayo Gómez Ramona | D11: M | E11: CG | F11: J | G11: SÍ | H11: SÍ | I11: 22985 | J11: =IF(C11="","",DATEDIF(I11,TODAY(),"Y")) -> 63 | K11: 44440977 | L11: Arquimedes,740 Hermosa Provincia | N11: 17 casadas EHP Dalila Coronado
A12: =IF(D12="","",COUNTA($D$4:$D12)) -> 9 | B12: =IF(C12="","",D12&F12&COUNTIFS($D$4:D12,D12,$F$4:F12,F12)) -> HB1 | C12: Aguilar Castro Alejandro | D12: H | E12: CM | F12: B | G12: SÍ | H12: SÍ | I12: 31199 | J12: =IF(C12="","",DATEDIF(I12,TODAY(),"Y")) -> 40 | K12: 3318418198 | L12: Cirujanos 652, Col. Lagos De Oriente
A13: =IF(D13="","",COUNTA($D$4:$D13)) -> 10 | B13: =IF(C13="","",D13&F13&COUNTIFS($D$4:D13,D13,$F$4:F13,F13)) -> MB3 | C13: Aguilar Chávez Judit Janai | D13: M | E13: JU | F13: B | G13: SÍ | H13: SÍ | I13: 35717 | J13: =IF(C13="","",DATEDIF(I13,TODAY(),"Y")) -> 28 | K13: 3335902493 | L13: Canaan, 3711, San Joaquin
A14: =IF(D14="","",COUNTA($D$4:$D14)) -> 11 | B14: =IF(C14="","",D14&F14&COUNTIFS($D$4:D14,D14,$F$4:F14,F14)) -> MS1 | C14: Aguilera Cortés Martha Leticia | D14: M | E14: CG | F14: S | G14: SÍ | H14: SÍ | I14: 27451 | J14: =IF(C14="","",DATEDIF(I14,TODAY(),"Y")) -> 51 | K14: 3318408100 | L14: Geografos, 717, Lagos De Oriente | N14: 13 casadas EHP Rosalia Palomar Soltero
A15: =IF(D15="","",COUNTA($D$4:$D15)) -> 12 | B15: =IF(C15="","",D15&F15&COUNTIFS($D$4:D15,D15,$F$4:F15,F15)) -> MS2 | C15: Aguilera Cortés Rocío | D15: M | E15: CM | F15: S | G15: SÍ | H15: SÍ | I15: 28387 | J15: =IF(C15="","",DATEDIF(I15,TODAY(),"Y")) -> 48 | K15: 3321854803 | L15: Gustavo Bas, 3567, Col. Miguel Hidalgo | N15: 12 Casadas EHP Alma Zamora de Joaquín
A16: =IF(D16="","",COUNTA($D$4:$D16)) -> 13 | B16: =IF(C16="","",D16&F16&COUNTIFS($D$4:D16,D16,$F$4:F16,F16)) -> MB4 | C16: Aguilera Salas Adalia Quiriabeth | D16: M | E16: CC | F16: B | G16: SÍ | H16: SÍ | I16: 33129 | J16: =IF(C16="","",DATEDIF(I16,TODAY(),"Y")) -> 35 | K16: 3313833507 | L16: Jardin Botanico,3490,Lagos de Oriente | M16: 39264
A17: =IF(D17="","",COUNTA($D$4:$D17)) -> 14 | B17: =IF(C17="","",D17&F17&COUNTIFS($D$4:D17,D17,$F$4:F17,F17)) -> MJ3 | C17: Ahumada Ibarra Ana Ismeria | D17: M | E17: JU | F17: J | G17: SÍ | H17: SÍ | I17: 36145 | J17: =IF(C17="","",DATEDIF(I17,TODAY(),"Y")) -> 27 | K17: 3325991783 | L17: Genaro 347, col. Miguel Hidalgo | M17: 45588 | N17: 4 señoritas EHP Ana Valenzuela Montaño
A18: =IF(D18="","",COUNTA($D$4:$D18)) -> 15 | B18: =IF(C18="","",D18&F18&COUNTIFS($D$4:D18,D18,$F$4:F18,F18)) -> HJ1 | C18: Ahumada Ibarra Gerson Raciel | D18: H | E18: CC | F18: J | H18: SÍ | I18: 37383 | J18: =IF(C18="","",DATEDIF(I18,TODAY(),"Y")) -> 23 | K18: 3315330744 | L18: Genaro Garcia 3341 | M18: 45610
A19: =IF(D19="","",COUNTA($D$4:$D19)) -> 16 | B19: =IF(C19="","",D19&F19&COUNTIFS($D$4:D19,D19,$F$4:F19,F19)) -> MB5 | C19: Ahumada Ibarra Lesslie | D19: M | E19: CC | F19: B | G19: SÍ | H19: SÍ | I19: 35434 | J19: =IF(C19="","",DATEDIF(I19,TODAY(),"Y")) -> 29 | K19: 3318436092 | L19: Telegrafistas 3483 Col Hermosa Provincia | M19: 43162
A20: =IF(D20="","",COUNTA($D$4:$D20)) -> 17 | B20: =IF(C20="","",D20&F20&COUNTIFS($D$4:D20,D20,$F$4:F20,F20)) -> MV2 | C20: Aldama Hernández Hortencia | D20: M | E20: CG | F20: V | H20: SÍ | I20: 24848 | J20: =IF(C20="","",DATEDIF(I20,TODAY(),"Y")) -> 58 | K20: 3311028337 | L20: Procuradores,596, Libertad
A21: =IF(D21="","",COUNTA($D$4:$D21)) -> 18 | B21: =IF(C21="","",D21&F21&COUNTIFS($D$4:D21,D21,$F$4:F21,F21)) -> HB2 | C21: Alegria Serrano Aram | D21: H | E21: JU | F21: B | G21: NO | H21: SÍ | I21: 37258 | J21: =IF(C21="","",DATEDIF(I21,TODAY(),"Y")) -> 24 | K21: 3331385646 | L21: Esbirna, 4007-A,Bethel
A22: =IF(D22="","",COUNTA($D$4:$D22)) -> 19 | B22: =IF(C22="","",D22&F22&COUNTIFS($D$4:D22,D22,$F$4:F22,F22)) -> ML1 | C22: Alegria Serrano Bethsaida | D22: M | E22: SO | F22: L | H22: SÍ | I22: 32374 | J22: =IF(C22="","",DATEDIF(I22,TODAY(),"Y")) -> 37 | K22: 3331080997 | L22: Jerusalen, 3417, Hermosa Provincia
A23: =IF(D23="","",COUNTA($D$4:$D23)) -> 20 | B23: =IF(C23="","",D23&F23&COUNTIFS($D$4:D23,D23,$F$4:F23,F23)) -> MV3 | C23: Almaguer Lugo Likhy | D23: M | E23: JU | F23: V | G23: SÍ | H23: SÍ | I23: 40483 | J23: =IF(C23="","",DATEDIF(I23,TODAY(),"Y")) -> 15 | K23: 3312926923 | L23: Privada de belen 87A | M23: 45678 | N23: 2 adolescentes EHP Nebai Zamora
A24: =IF(D24="","",COUNTA($D$4:$D24)) -> 21 | B24: =IF(C24="","",D24&F24&COUNTIFS($D$4:D24,D24,$F$4:F24,F24)) -> MJ4 | C24: Almaguer Lugo Quiriath Yearim | D24: M | E24: JU | F24: J | G24: SÍ | H24: SÍ | I24: 39854 | J24: =IF(C24="","",DATEDIF(I24,TODAY(),"Y")) -> 17 | K24: 3326648344 | L24: Privada de Belén 87A Hermosa provincia | M24: 45792 | N24: 1 señoritas EHP Sabdi Bebai Valle Balmaceda
A25: =IF(D25="","",COUNTA($D$4:$D25)) -> 22 | B25: =IF(C25="","",D25&F25&COUNTIFS($D$4:D25,D25,$F$4:F25,F25)) -> ML2 | C25: Almaraz Nuñez Alejandra | D25: M | E25: CM | F25: L | G25: SÍ | H25: SÍ | I25: 28305 | J25: =IF(C25="","",DATEDIF(I25,TODAY(),"Y")) -> 48 | K25: 3334681520 | L25: Cairo 1317 int 420, San Eugenio | M25: 43641 | N25: Conversión
A26: =IF(D26="","",COUNTA($D$4:$D26)) -> 23 | B26: =IF(C26="","",D26&F26&COUNTIFS($D$4:D26,D26,$F$4:F26,F26)) -> MB6 | C26: Alonso Bravo Karen Janed | D26: M | E26: CM | F26: B | G26: SÍ | H26: SÍ | I26: 31778 | J26: =IF(C26="","",DATEDIF(I26,TODAY(),"Y")) -> 39 | K26: 6612394252 | L26: Sin Direccion
A27: =IF(D27="","",COUNTA($D$4:$D27)) -> 24 | B27: =IF(C27="","",D27&F27&COUNTIFS($D$4:D27,D27,$F$4:F27,F27)) -> MMa1 | C27: Alonso Chavando Santa | D27: M | E27: CG | F27: Ma | G27: SÍ | H27: SÍ | I27: 27032 | J27: =IF(C27="","",DATEDIF(I27,TODAY(),"Y")) -> 52 | K27: 3333551915 | L27: Presa modelo 480, Lagos de Oriente | M27: 45986 | N27: 13 Casadas, EHP Rosalía Palomar Soltero
A28: =IF(D28="","",COUNTA($D$4:$D28)) -> 25 | B28: =IF(C28="","",D28&F28&COUNTIFS($D$4:D28,D28,$F$4:F28,F28)) -> MB7 | C28: Alonso León Ashley | D28: M | E28: JU | F28: B | G28: SÍ | H28: SÍ | I28: 36577 | J28: =IF(C28="","",DATEDIF(I28,TODAY(),"Y")) -> 26 | K28: 36063314 | L28: Privada De Belen, 28-S, Hermosa Provincia
A29: =IF(D29="","",COUNTA($D$4:$D29)) -> 26 | B29: =IF(C29="","",D29&F29&COUNTIFS($D$4:D29,D29,$F$4:F29,F29)) -> HD1 | C29: Alonso León David | D29: H | E29: CM | F29: D | G29: SÍ | H29: SÍ | I29: 35119 | J29: =IF(C29="","",DATEDIF(I29,TODAY(),"Y")) -> 30 | L29: Privada de Belén 28, Hermosa Provincia, | M29: 43754 | N29: 2 casados EHP David Henoc Pardo Rosales
A30: =IF(D30="","",COUNTA($D$4:$D30)) -> 27 | B30: =IF(C30="","",D30&F30&COUNTIFS($D$4:D30,D30,$F$4:F30,F30)) -> HB3 | C30: Alonso Rivera Jonathán | D30: H | E30: CG | F30: B | G30: SÍ | H30: SÍ | I30: 23639 | J30: =IF(C30="","",DATEDIF(I30,TODAY(),"Y")) -> 61 | K30: 3317061837 | L30: Priv. Belen 28, Hermosa Provincia
A31: =IF(D31="","",COUNTA($D$4:$D31)) -> 28 | B31: =IF(C31="","",D31&F31&COUNTIFS($D$4:D31,D31,$F$4:F31,F31)) -> HS2 | C31: Alpizar Flores Hipólito | D31: H | E31: CG | F31: S | G31: SÍ | H31: SÍ | I31: 21775 | J31: =IF(C31="","",DATEDIF(I31,TODAY(),"Y")) -> 66 | K31: 3312509476 | L31: Presa Modelo, 489, Lagos De Oriente | N31: 13 Casados, EHP David Cuevas Arellano
A32: =IF(D32="","",COUNTA($D$4:$D32)) -> 29 | B32: =IF(C32="","",D32&F32&COUNTIFS($D$4:D32,D32,$F$4:F32,F32)) -> MD1 | C32: Alpizar Velasco Merari Eulalia | D32: M | E32: SO | F32: D | H32: SÍ | I32: 30269 | J32: =IF(C32="","",DATEDIF(I32,TODAY(),"Y")) -> 43 | K32: 3333389355 | L32: Presa Modelo 489, Lagos de Oriente | M32: 44631 | N32: 2° solas, EHP Ruth Aguilar S
A33: =IF(D33="","",COUNTA($D$4:$D33)) -> 30 | B33: =IF(C33="","",D33&F33&COUNTIFS($D$4:D33,D33,$F$4:F33,F33)) -> MB8 | C33: Altamirano Sanchez Berenice | D33: M | E33: JU | F33: B | G33: SÍ | H33: SÍ | I33: 34240 | J33: =IF(C33="","",DATEDIF(I33,TODAY(),"Y")) -> 32 | K33: 3338285694 | L33: Pablo Valdez, 3811,int i4,san fransisco
A34: =IF(D34="","",COUNTA($D$4:$D34)) -> 31 | B34: =IF(C34="","",D34&F34&COUNTIFS($D$4:D34,D34,$F$4:F34,F34)) -> HB4 | C34: Alvarado Baldenegro Adrián | D34: H | E34: JU | F34: B | G34: SÍ | H34: SÍ | I34: 37176 | J34: =IF(C34="","",DATEDIF(I34,TODAY(),"Y")) -> 24 | K34: 3317216647 | L34: Ramon Aldama, 3702, 2A. Secc. H P.
A35: =IF(D35="","",COUNTA($D$4:$D35)) -> 32 | B35: =IF(C35="","",D35&F35&COUNTIFS($D$4:D35,D35,$F$4:F35,F35)) -> HB5 | C35: Alvarado Chávez Giezi Eliab | D35: H | E35: JU | F35: B | G35: SÍ | H35: SÍ | I35: 38555 | J35: =IF(C35="","",DATEDIF(I35,TODAY(),"Y")) -> 20 | L35: Gustavo Baz 3822, Lopez Velarde | M35: 43641 | N35: 1 adolescentes EHP Carlos Hernandez Larios
A36: =IF(D36="","",COUNTA($D$4:$D36)) -> 33 | B36: =IF(C36="","",D36&F36&COUNTIFS($D$4:D36,D36,$F$4:F36,F36)) -> HB6 | C36: Alvarado Chavez Jacob | D36: H | E36: JU | F36: B | G36: SÍ | H36: SÍ | I36: 37852 | J36: =IF(C36="","",DATEDIF(I36,TODAY(),"Y")) -> 22 | K36: 3314707502 | L36: Gustavo Baz 3822, Lopez Velarde | M36: 42943
A37: =IF(D37="","",COUNTA($D$4:$D37)) -> 34 | B37: =IF(C37="","",D37&F37&COUNTIFS($D$4:D37,D37,$F$4:F37,F37)) -> MD2 | C37: Alvarado Enedina | D37: M | E37: CM | F37: D | G37: SÍ | H37: SÍ | I37: 30735 | J37: =IF(C37="","",DATEDIF(I37,TODAY(),"Y")) -> 42 | K37: 3310853988 | L37: Presa Osorio #3590, Lagos de oriente. | M37: 45227 | N37: 10 de casadas D. Eva Garcia de Joaquín
A38: =IF(D38="","",COUNTA($D$4:$D38)) -> 35 | B38: =IF(C38="","",D38&F38&COUNTIFS($D$4:D38,D38,$F$4:F38,F38)) -> HB7 | C38: Alvarez Callejas Francisco Javier | D38: H | E38: CM | F38: B | G38: SÍ | H38: SÍ | I38: 28235 | J38: =IF(C38="","",DATEDIF(I38,TODAY(),"Y")) -> 49 | K38: 4427678326 | L38: Pablo Valdez 3971, Velarde | M38: 43700 | N38: 6 Casados, EHP Placido Perez Silva
A39: =IF(D39="","",COUNTA($D$4:$D39)) -> 36 | B39: =IF(C39="","",D39&F39&COUNTIFS($D$4:D39,D39,$F$4:F39,F39)) -> MB9 | C39: Alvarez Navarro María | D39: M | E39: CG | F39: B | G39: SÍ | H39: SÍ | I39: 17662 | J39: =IF(C39="","",DATEDIF(I39,TODAY(),"Y")) -> 77 | K39: 3314822846 | L39: Presa Oviachic 837 | M39: 43644 | N39: 17 casadas EHP Noemi Avalos
A40: =IF(D40="","",COUNTA($D$4:$D40)) -> 37 | B40: =IF(C40="","",D40&F40&COUNTIFS($D$4:D40,D40,$F$4:F40,F40)) -> HV2 | C40: Alvarez Salas Asaf Ismael | D40: H | E40: JU | F40: V | G40: SÍ | H40: SÍ | I40: 40459 | J40: =IF(C40="","",DATEDIF(I40,TODAY(),"Y")) -> 15 | K40: 3339798062 | L40: Emilio Rabaza #4056, Los Arrayanes | M40: 45686 | N40: 2 adolescentes D.E. Sergio Altamirano Garcia
A41: =IF(D41="","",COUNTA($D$4:$D41)) -> 38 | B41: =IF(C41="","",D41&F41&COUNTIFS($D$4:D41,D41,$F$4:F41,F41)) -> HL2 | C41: Alvarez Toala Uziel | D41: H | E41: JU | F41: L | H41: SÍ | I41: 40046 | J41: =IF(C41="","",DATEDIF(I41,TODAY(),"Y")) -> 16 | L41: Cairo #346 | M41: 45340 | N41: 2 adolescentes, EHP Sergio Altamirano
...

Sheet Asistencia
A1: =UPPER(TEXT($C$19,"mmmm aaa")) -> ABRIL LUN | AI1: Total de oraciones del mes, a las que asistió cada hermano.
C4: 1 | D4: H | E4: j | F4: ="Herman"&IF(D4="H","o","a")&"s del día: "&PROPER(VLOOKUP(E4,Tablas!$A$3:$B$9,2,0)) -> Hermanos del día: Jueves
A6: RESUMEN MENSUAL | AI6: Total de oraciones asistidas al mes
A7: ¿Hoy llegaron mas hermanos a la oración? Por favor anótalos en el cuadro. | C7: =C18 -> L | D7: =D18 -> M | E7: =E18 -> M | F7: =F18 -> J | G7: =G18 -> V | H7: =H18 -> S | I7: =I18 -> D | J7: =J18 -> L | ... AG7: =AG18
C8: =C19 -> 45383 | D8: =D19 -> 45384 | E8: =E19 -> 45385 | F8: =F19 -> 45386 | G8: =G19 -> 45387 | H8: =H19 -> 45388 | I8: =I19 -> 45389 | J8: =J19 -> 45390 | ... AG8: =AG19 | AI8: 5 | AK8: C | AM8: S / J
C9: 5 | D9: 5 | E9: 5 | F9: 5 | G9: 5 | H9: 5 | I9: 5 | J9: 5 | K9: 5 | L9: 5 | M9: 5 | N9: 5 | O9: 5 | P9: 5 | Q9: 5 | R9: 5 | S9: 5 | T9: 5 | U9: 5 | V9: 5 | W9: 5 | X9: 5 | Y9: 5 | Z9: 5 | AA9: 5 | AB9: 5 | AC9: 5 | AD9: 5 | AE9: =IF(AE8="","",5) -> 5 | AF9: =IF(AF8="","",5) -> 5 | AG9: =IF(AG8="","",5)
C10: =IF(C$7="D","D",9) -> 9 | D10: =IF(D$7="D","D",9) -> 9 | E10: =IF(E$7="D","D",9) -> 9 | F10: =IF(F$7="D","D",9) -> 9 | G10: =IF(G$7="D","D",9) -> 9 | H10: =IF(H$7="D","D",9) -> 9 | I10: =IF(I$7="D","D",9) -> D | J10: =IF(J$7="D","D",9) -> 9 | ... AD10: =IF(AD$7="D","D",9) -> D | AE10: =IF(AE7="","",IF(AE$7="D","D",9)) -> 9 | AF10: =IF(AF7="","",IF(AF$7="D","D",9)) -> 9 | AG10: =IF(AG7="","",IF(AG$7="D","D",9)) | AI10: 9 | AK10: D
C11: =IF(OR(C$7="D",C$7="J"),"S",6) -> 6 | D11: =IF(OR(D$7="D",D$7="J"),"S",6) -> 6 | E11: =IF(OR(E$7="D",E$7="J"),"S",6) -> 6 | F11: =IF(OR(F$7="D",F$7="J"),"S",6) -> S | G11: =IF(OR(G$7="D",G$7="J"),"S",6) -> 6 | H11: =IF(OR(H$7="D",H$7="J"),"S",6) -> 6 | I11: =IF(OR(I$7="D",I$7="J"),"S",6) -> S | J11: =IF(OR(J$7="D",J$7="J"),"S",6) -> 6 | ... AD11: =IF(OR(AD$7="D",AD$7="J"),"S",6) -> S | AE11: =IF(AE7="","",IF(OR(AE$7="D",AE$7="J"),"S",6)) -> 6 | AF11: =IF(AF7="","",IF(OR(AF$7="D",AF$7="J"),"S",6)) -> 6 | AG11: =IF(AG7="","",IF(OR(AG$7="D",AG$7="J"),"S",6))
C12: =IF(OR(C$7="D",C$7="J"),"","C") -> C | D12: =IF(OR(D$7="D",D$7="J"),"","C") -> C | E12: =IF(OR(E$7="D",E$7="J"),"","C") -> C | F12: =IF(OR(F$7="D",F$7="J"),"","C") | G12: =IF(OR(G$7="D",G$7="J"),"","C") -> C | H12: =IF(OR(H$7="D",H$7="J"),"","C") -> C | I12: =IF(OR(I$7="D",I$7="J"),"","C") | J12: =IF(OR(J$7="D",J$7="J"),"","C") -> C | ... AD12: =IF(OR(AD$7="D",AD$7="J"),"","C") | AE12: =IF(AE7="","",IF(OR(AE$7="D",AE$7="J"),"","C")) -> C | AF12: =IF(AF7="","",IF(OR(AF$7="D",AF$7="J"),"","C")) -> C | AG12: =IF(AG7="","",IF(OR(AG$7="D",AG$7="J"),"","C")) | AI12: 6 | AK12: S / D
C14: ="Oraciones de 5 ……….. "&COUNTIF($C$9:$AG$12,5) -> Oraciones de 5 ……….. 30 | L14: ="Oraciones de 6 …….….. "&COUNTIF($C$9:$AG$12,6) -> Oraciones de 6 …….….. 22 | W14: ="Dominicales ……….……....….. "&COUNTIF($C$9:$AG$12,"D") -> Dominicales ……….……....….. 4
C15: ="Oraciones de 9 ……….. "&COUNTIF($C$9:$AG$12,9) -> Oraciones de 9 ……….. 26 | L15: ="Consagraciones ……….. "&COUNTIF($C$9:$AG$12,"C") -> Consagraciones ……….. 22 | W15: ="Servicios (Dom/Jue) ……….. "&COUNTIF($C$7:$AG$7,"D")&" / "&COUNTIF($C$7:$AG$7,"J") -> Servicios (Dom/Jue) ……….. 4 / 4
A17: ="LISTA DE ASISTENCIA A LAS ORACIONES EN EL MES DE "&UPPER(TEXT(C19,"mmmm / aaa"))&" - HERMAN"&IF(D4="H","O","A")&"S DEL DÍA "&UPPER(VLOOKUP(E4,Tablas!$A$3:$B$9,2,0)) -> LISTA DE ASISTENCIA A LAS ORACIONES EN EL MES DE ABRIL / LUN - HERMANOS DEL DÍA JUEVES
A18: No. | B18: N O M B R E S | C18: =UPPER(LEFT(TEXT(WEEKDAY(C19),"ddd"),1)) -> L | D18: =UPPER(LEFT(TEXT(WEEKDAY(D19),"ddd"),1)) -> M | E18: =UPPER(LEFT(TEXT(WEEKDAY(E19),"ddd"),1)) -> M | F18: =UPPER(LEFT(TEXT(WEEKDAY(F19),"ddd"),1)) -> J | G18: =UPPER(LEFT(TEXT(WEEKDAY(G19),"ddd"),1)) -> V | H18: =UPPER(LEFT(TEXT(WEEKDAY(H19),"ddd"),1)) -> S | I18: =UPPER(LEFT(TEXT(WEEKDAY(I19),"ddd"),1)) -> D | J18: =UPPER(LEFT(TEXT(WEEKDAY(J19),"ddd"),1)) -> L | ... AD18: =UPPER(LEFT(TEXT(WEEKDAY(AD19),"ddd"),1)) -> D | AE18: =IF(AE19="", "",UPPER(LEFT(TEXT(WEEKDAY(AE19),"ddd"),1))) -> L | AF18: =IF(AF19="", "",UPPER(LEFT(TEXT(WEEKDAY(AF19),"ddd"),1))) -> M | AG18: =IF(AG19="", "",UPPER(LEFT(TEXT(WEEKDAY(AG19),"ddd"),1))) | AI18: .. Cual será tu record ?
C19: 45383 | D19: =+C19+1 -> 45384 | E19: =+D19+1 -> 45385 | F19: =+E19+1 -> 45386 | G19: =+F19+1 -> 45387 | H19: =+G19+1 -> 45388 | I19: =+H19+1 -> 45389 | J19: =+I19+1 -> 45390 | K19: =+J19+1 -> 45391 | ... AD19: =+AC19+1 -> 45410 | AE19: =IF(MONTH(AD19+1)=MONTH(AD19),AD19+1,"") -> 45411 | AF19: =IF(AE19="","",IF(MONTH(AE19+1)=MONTH(AE19),AE19+1,"")) -> 45412 | AG19: =IF(AF19="","",IF(MONTH(AF19+1)=MONTH(AF19),AF19+1,"")) | AI19: D | AJ19: S | AK19: C | AL19: 5 | AM19: 9 | AN19: 6
A20: 1
A21: 2
A22: 3
A23: 4
A24: 5
A25: 6
A26: 7
A27: 8
A28: 9
A29: 10
A30: 11
A31: 12
... A40: 21
A41: 22 | B41: =IF(ISERROR(VLOOKUP($D$4&$E$4&$A41,'Lista General'!$B$4:$C$723,2,0)),"",VLOOKUP($D$4&$E$4&$A41,'Lista General'!$B$4:$C$723,2,0))
A42: 23 | B42: =IF(ISERROR(VLOOKUP($D$4&$E$4&$A42,'Lista General'!$B$4:$C$723,2,0)),"",VLOOKUP($D$4&$E$4&$A42,'Lista General'!$B$4:$C$723,2,0))
A43: 24 | B43: =IF(ISERROR(VLOOKUP($D$4&$E$4&$A43,'Lista General'!$B$4:$C$723,2,0)),"",VLOOKUP($D$4&$E$4&$A43,'Lista General'!$B$4:$C$723,2,0))
A44: 25 | B44: =IF(ISERROR(VLOOKUP($D$4&$E$4&$A44,'Lista General'!$B$4:$C$723,2,0)),"",VLOOKUP($D$4&$E$4&$A44,'Lista General'!$B$4:$C$723,2,0))
A45: 26 | B45: =IF(ISERROR(VLOOKUP($D$4&$E$4&$A45,'Lista General'!$B$4:$C$723,2,0)),"",VLOOKUP($D$4&$E$4&$A45,'Lista General'!$B$4:$C$723,2,0))
A46: 27 | B46: =IF(ISERROR(VLOOKUP($D$4&$E$4&$A46,'Lista General'!$B$4:$C$723,2,0)),"",VLOOKUP($D$4&$E$4&$A46,'Lista General'!$B$4:$C$723,2,0))
A47: 28 | B47: =IF(ISERROR(VLOOKUP($D$4&$E$4&$A47,'Lista General'!$B$4:$C$723,2,0)),"",VLOOKUP($D$4&$E$4&$A47,'Lista General'!$B$4:$C$723,2,0))
A48: 29 | B48: =IF(ISERROR(VLOOKUP($D$4&$E$4&$A48,'Lista General'!$B$4:$C$723,2,0)),"",VLOOKUP($D$4&$E$4&$A48,'Lista General'!$B$4:$C$723,2,0))
A49: 30 | B49: =IF(ISERROR(VLOOKUP($D$4&$E$4&$A49,'Lista General'!$B$4:$C$723,2,0)),"",VLOOKUP($D$4&$E$4&$A49,'Lista General'!$B$4:$C$723,2,0))
A50: 31 | B50: =IF(ISERROR(VLOOKUP($D$4&$E$4&$A50,'Lista General'!$B$4:$C$723,2,0)),"",VLOOKUP($D$4&$E$4&$A50,'Lista General'!$B$4:$C$723,2,0))
A51: 32 | B51: =IF(ISERROR(VLOOKUP($D$4&$E$4&$A51,'Lista General'!$B$4:$C$723,2,0)),"",VLOOKUP($D$4&$E$4&$A51,'Lista General'!$B$4:$C$723,2,0))
A52: 33 | B52: =IF(ISERROR(VLOOKUP($D$4&$E$4&$A52,'Lista General'!$B$4:$C$723,2,0)),"",VLOOKUP($D$4&$E$4&$A52,'Lista General'!$B$4:$C$723,2,0))
... A119: 100 | B119: =IF(ISERROR(VLOOKUP($D$4&$E$4&$A119,'Lista General'!$B$4:$C$723,2,0)),"",VLOOKUP($D$4&$E$4&$A119,'Lista General'!$B$4:$C$723,2,0))

Sheet Guardias
C1: Asistencia al día ofrecido para
C2: la Obra del Señor
E3: CORRESPONDIENTE AL MES DE | F3: 43221
B4: =IF(Asistencia!$D$4="H","RESPONSABLE DEL DÍA HNO.","COORDINADORA HNA.") -> RESPONSABLE DEL DÍA HNO. | C4: =UPPER(VLOOKUP(J4,Tablas!$B$3:$D$9,IF(Asistencia!$D$4="H",2,3),0)) -> GOMEZ QUINTERO JESUS | F4: 7 | I4: DÍA: | J4: =VLOOKUP(Asistencia!$E$4,Tablas!$A$3:$B$9,2,0) -> JUEVES
C5: Fecha de la semana al mes correspondiente
A6: No. | B6: N O M B R E | M6: TOTAL DE ASISTENCIAS
C7: entrada | D7: salida | E7: entrada | F7: salida | G7: entrada | H7: salida | I7: entrada | J7: salida | K7: entrada | L7: salida
A8: =Asistencia!A20 -> 1 | B8: =Asistencia!B20
A9: =Asistencia!A21 -> 2 | B9: =Asistencia!B21
A10: =Asistencia!A22 -> 3 | B10: =Asistencia!B22
A11: =Asistencia!A23 -> 4 | B11: =Asistencia!B23
A12: =Asistencia!A24 -> 5 | B12: =Asistencia!B24
A13: =Asistencia!A25 -> 6 | B13: =Asistencia!B25
A14: =Asistencia!A26 -> 7 | B14: =Asistencia!B26
A15: =Asistencia!A27 -> 8 | B15: =Asistencia!B27
A16: =Asistencia!A28 -> 9 | B16: =Asistencia!B28
A17: =Asistencia!A29 -> 10 | B17: =Asistencia!B29
A18: =Asistencia!A30 -> 11 | B18: =Asistencia!B30
A19: =Asistencia!A31 -> 12 | B19: =Asistencia!B31
... A38: =Asistencia!A50 -> 31 | B38: =Asistencia!B50
A39: =Asistencia!A51 -> 32
A40: =Asistencia!A52 -> 33
A41: =Asistencia!A53 -> 34 | B41: =Asistencia!B53
A42: =Asistencia!A54 -> 35 | B42: =Asistencia!B54
A43: =Asistencia!A55 -> 36 | B43: =Asistencia!B55
A44: =Asistencia!A56 -> 37 | B44: =Asistencia!B56
A45: =Asistencia!A57 -> 38 | B45: =Asistencia!B57
A46: =Asistencia!A58 -> 39 | B46: =Asistencia!B58
A47: =Asistencia!A59 -> 40 | B47: =Asistencia!B59
A48: =Asistencia!A60 -> 41 | B48: =Asistencia!B60
A49: =Asistencia!A61 -> 42 | B49: =Asistencia!B61
A50: =Asistencia!A62 -> 43 | B50: =Asistencia!B62
A51: =Asistencia!A63 -> 44 | B51: =Asistencia!B63
A52: =Asistencia!A64 -> 45 | B52: =Asistencia!B64
... A107: =Asistencia!A119 -> 100 | B107: =Asistencia!B119
B108: .
B109: .
B110: Porque nuestra gloria es esta: el testimonio de nuestra conciencia… 2 Cor. 1 : 12
B111: .
B112: ="AL FINAL DEL MES, FAVOR DE INFORMAR SI ALGUN"&IF(Asistencia!$D$4="H","O","A")&" DE L"&IF(Asistencia!$D$4="H","O","A")&"S HERMAN"&IF(Asistencia!$D$4="H","O","A")&"S, TUVO ALGUNA BENDICIÓN O EVENTO DE LOS ABAJO DESCRITOS Dios les pague." -> AL FINAL DEL MES, FAVOR DE INFORMAR SI ALGUNO DE LOS HERMANOS, TUVO ALGUNA BENDICIÓN O EVENTO DE LOS ABAJO DESCRITOS Dios les pague.
...

Sheet Hoja1
C1: Asistencia al día ofrecido para
C2: la Obra del Señor
E3: CORRESPONDIENTE AL MES DE | F3: 43252
B4: COORDINADORA HNA. | C4: SÁNCHEZ RAMOS MARÍA EMILIA | I4: DÍA: | J4: MARTES
C5: Fecha de la semana al mes correspondiente
A6: No. | B6: N O M B R E | M6: TOTAL DE ASISTENCIAS
C7: entrada | D7: salida | E7: entrada | F7: salida | G7: entrada | H7: salida | I7: entrada | J7: salida | K7: entrada | L7: salida
A8: 1 | B8: Alegria Serrano Bethsaida
A9: 2 | B9: Alonso León Ashley
A10: 3 | B10: Aparicio Guatemala Claudia Mireya
A11: 4 | B11: Arana Palacios Elda Jazmín
A12: 5 | B12: Barba Romo Esperanza
A13: 6 | B13: Camarillo Mendoza Eunice
A14: 7 | B14: Camilo Solís Judith
A15: 8 | B15: Chávez Ortiz Ma De Lourdes
A16: 9 | B16: Flores Calderón María
A17: 10 | B17: Flores García Yolanda
A18: 11 | B18: García García Juana Ma
A19: 12 | B19: Gómez López Esther
... A44: 37 | B44: Vera Gutiérrez Guillermina Adela
B45: .
B46: .
B47: Porque nuestra gloria es esta: el testimonio de nuestra conciencia… 2 Cor. 1 : 12
B48: .
B49: AL FINAL DEL MES, FAVOR DE INFORMAR SI ALGUNA DE LAS HERMANAS, TUVO ALGUNA BENDICIÓN O EVENTO DE LOS ABAJO DESCRITOS Dios les pague.
B50: .
B51: Nacimientos_______ Defunciones_______ Matrimonios________ B. en Esp. Santo________ B. en agua._______ Pres. de niños_______

Sheet Altas
C1: ="Total: "&SUBTOTAL(3,$C$4:$C$10) -> Total: 7
A3: No. | B3: Llave | C3: N O M B R E | D3: G | E3: E.C. | F3: DIA | G3: CARTA | H3: REG. | I3: F. NAC. | J3: EDAD | K3: TEL. | L3: DIRECCION | M3: Fecha ingreso | N3: OBS.
B4: =IF(C4="","",D4&F4&COUNTIFS($D$4:D4,D4,$F$4:F4,F4)) -> HJ1 | C4: Jacob Alvarado Chavez | D4: H | E4: JU | F4: J | G4: SÍ | H4: SÍ | I4: 37852 | J4: =IF(C4="","",DATEDIF(I4,TODAY(),"Y")) -> 22 | K4: 3314707502 | L4: Gustavo Baz 3822, Lopez Velarde | M4: 42943
B5: =IF(C5="","",D5&F5&COUNTIFS($D$4:D5,D5,$F$4:F5,F5)) -> HMa1 | C5: Victorin Martinez Pedro | D5: H | E5: CG | F5: Ma | G5: SÍ | H5: SÍ | I5: 16742 | J5: =IF(C5="","",DATEDIF(I5,TODAY(),"Y")) -> 80 | K5: 3314989868 | L5: Jerusalen 3402, Hermosa Provincia | M5: 43002
B6: =IF(C6="","",D6&F6&COUNTIFS($D$4:D6,D6,$F$4:F6,F6)) -> HD1 | C6: Cabrera Comunidad Raul | D6: H | E6: JU | F6: D | G6: SÍ | H6: SÍ | I6: 35210 | J6: =IF(C6="","",DATEDIF(I6,TODAY(),"Y")) -> 29 | K6: 3334973578 | L6: Presa Osorio | M6: 43003
B7: =IF(C7="","",D7&F7&COUNTIFS($D$4:D7,D7,$F$4:F7,F7)) -> MS1 | C7: Pierrez Perez Citlali | D7: M | E7: JU | F7: S | G7: SÍ | H7: SÍ | I7: 37605 | J7: =IF(C7="","",DATEDIF(I7,TODAY(),"Y")) -> 23 | K7: 3321101304 | L7: Canaan 3957, San Joaquin | M7: 42983
B8: =IF(C8="","",D8&F8&COUNTIFS($D$4:D8,D8,$F$4:F8,F8)) -> MD1 | C8: Cardenas Cervantes Nancy Guadalupe | D8: M | E8: JU | F8: D | G8: SÍ | H8: SÍ | I8: 37188 | J8: =IF(C8="","",DATEDIF(I8,TODAY(),"Y")) -> 24 | K8: 3318570480 | L8: Presa la Escondida 3977, San Joaquin | M8: 42985
B9: =IF(C9="","",D9&F9&COUNTIFS($D$4:D9,D9,$F$4:F9,F9)) -> MD2 | C9: Martinez Morales Ruth | D9: M | E9: JU | F9: D | G9: SÍ | H9: SÍ | I9: 30146 | J9: =IF(C9="","",DATEDIF(I9,TODAY(),"Y")) -> 43 | K9: 3322426265 | L9: Presa Palmito,689, San Joaquin | M9: 42992
B10: =IF(C10="","",D10&F10&COUNTIFS($D$4:D10,D10,$F$4:F10,F10)) -> MV1 | C10: Reyes Aguilera Athalia Ismerai | D10: M | E10: JU | F10: V | G10: SÍ | H10: SÍ | I10: 37743 | J10: =IF(C10="","",DATEDIF(I10,TODAY(),"Y")) -> 22 | K10: 3319964457 | L10: Geografos 717, Lagos de Oriente | M10: 43045 | N10: 2 de adolescentes
B11: =IF(C11="","",D11&F11&COUNTIFS($D$4:D11,D11,$F$4:F11,F11)) -> MS2 | C11: Nimra Uribe Ceron | D11: M | E11: JU | F11: S | G11: NO | H11: SÍ | I11: 35070 | J11: =IF(C11="","",DATEDIF(I11,TODAY(),"Y")) -> 30 | K11: 3317083896 | L11: Manuel Santibañez, 3572, Col. Miguel Hidalgo | M11: 43074
B12: =IF(C12="","",D12&F12&COUNTIFS($D$4:D12,D12,$F$4:F12,F12)) -> MV2 | C12: Orellada Perez Dalila | D12: M | E12: SO | F12: V | G12: SÍ | H12: SÍ | I12: 25420 | J12: =IF(C12="","",DATEDIF(I12,TODAY(),"Y")) -> 56 | L12: Demostenes, 971, Col. Libertad | M12: 43078
B13: =IF(C13="","",D13&F13&COUNTIFS($D$4:D13,D13,$F$4:F13,F13)) -> MJ1 | C13: Martinez Pulido Maria | D13: M | E13: SO | F13: J | G13: SÍ | H13: SÍ | J13: =IF(C13="","",DATEDIF(I13,TODAY(),"Y")) -> 126 | K13: 3541080321 | L13: Presa Oviachic, 670-3, San Joaquin | M13: 43117 | N13: Los reyes, Michoacan
B14: =IF(C14="","",D14&F14&COUNTIFS($D$4:D14,D14,$F$4:F14,F14)) -> MS3 | C14: Pierrez Carillo Diana Jazmin | D14: M | E14: JU | F14: S | G14: SÍ | H14: SÍ | I14: 36527 | J14: =IF(C14="","",DATEDIF(I14,TODAY(),"Y")) -> 26 | K14: 3319996068 | L14: Presa Santa Rosa, 587-A, Lagos De Oriente | M14: 43115 | N14: 1 señoritas
B15: =IF(C15="","",D15&F15&COUNTIFS($D$4:D15,D15,$F$4:F15,F15)) -> MS4 | C15: Espinoza Meza Rebeca Sarai | D15: M | E15: JU | F15: S | G15: SÍ | H15: SÍ | I15: 37940 | J15: =IF(C15="","",DATEDIF(I15,TODAY(),"Y")) -> 22 | K15: 3311636973 | L15: Nazareth, 629, Hermosa Provincia | M15: 43103 | N15: 1 adolescentes
B16: =IF(C16="","",D16&F16&COUNTIFS($D$4:D16,D16,$F$4:F16,F16)) -> MV3 | C16: Rodriguez Alfaro Ana Margarita | D16: M | E16: CG | F16: V | G16: SÍ | H16: SÍ | I16: 24316 | J16: =IF(C16="","",DATEDIF(I16,TODAY(),"Y")) -> 59 | K16: 3313196310 | L16: Presa Solis, 3932-3, Lagos de Oriente | M16: 43103 | N16: 15 casadas
B17: =IF(C17="","",D17&F17&COUNTIFS($D$4:D17,D17,$F$4:F17,F17)) -> HV1 | C17: Ochoa Vargas Daniel | D17: H | E17: JU | F17: V | G17: SÍ | H17: SÍ | I17: 34213 | J17: =IF(C17="","",DATEDIF(I17,TODAY(),"Y")) -> 32 | K17: 3311316545 | M17: 43123 | N17: batallaon de comala colima
B18: =IF(C18="","",D18&F18&COUNTIFS($D$4:D18,D18,$F$4:F18,F18)) -> HS1 | C18: Flores Valencia Fines Edrei | D18: H | E18: JU | F18: S | G18: NO | H18: SÍ | I18: 37816 | J18: =IF(C18="","",DATEDIF(I18,TODAY(),"Y")) -> 22 | K18: 3331191945 | L18: Josefa Ortiz de Dominguez, | M18: 43128 | N18: carta pendiente
B19: =IF(C19="","",D19&F19&COUNTIFS($D$4:D19,D19,$F$4:F19,F19)) -> HJ2 | C19: Cuenca Ramirez Magdiel Dibai | D19: H | E19: JU | F19: J | G19: SÍ | H19: SÍ | I19: 33933 | J19: =IF(C19="","",DATEDIF(I19,TODAY(),"Y")) -> 33 | K19: 3318254382 | L19: Jardines Japoneses, 3537-A, Lagos de Oriente | M19: 43115 | N19: 4 jovenes
B20: =IF(C20="","",D20&F20&COUNTIFS($D$4:D20,D20,$F$4:F20,F20)) -> HD2 | C20: Bravo Santamaria Isaac Emanuel | D20: H | E20: JU | F20: D | G20: SÍ | H20: SÍ | I20: 36609 | J20: =IF(C20="","",DATEDIF(I20,TODAY(),"Y")) -> 26 | K20: 5537782007 | L20: Escalon,630, Lagos de Oriente | M20: 43107 | N20: carta entregada meses antes
B21: =IF(C21="","",D21&F21&COUNTIFS($D$4:D21,D21,$F$4:F21,F21)) -> HD3 | C21: Lechuga Oliva Naason Efrain | D21: H | E21: JU | F21: D | G21: SÍ | H21: SÍ | I21: 34395 | J21: =IF(C21="","",DATEDIF(I21,TODAY(),"Y")) -> 32 | K21: 3316717383 | L21: Telegrafistas, 3483, Hermosa Provincia | M21: 43101 | N21: las carolinas, Coahuila
B22: =IF(C22="","",D22&F22&COUNTIFS($D$4:D22,D22,$F$4:F22,F22)) -> MS5 | C22: Lesslie Ahumada Ibarra | D22: M | E22: JU | F22: S | G22: SÍ | H22: SÍ | I22: 35434 | J22: =IF(C22="","",DATEDIF(I22,TODAY(),"Y")) -> 29 | K22: 3318436092 | L22: Telegrafistas 3483 Col Hermosa Provincia | M22: 43162 | N22: Tecoman Colima
B23: =IF(C23="","",D23&F23&COUNTIFS($D$4:D23,D23,$F$4:F23,F23)) -> HV2 | C23: Naason Neiel Mares Osuna | D23: H | E23: JU | F23: V | G23: SÍ | H23: SÍ | I23: 37866 | J23: =IF(C23="","",DATEDIF(I23,TODAY(),"Y")) -> 22 | K23: 3317712426 | L23: Miguel Leon Portillo 1116 col San Francisco | M23: 43171 | N23: 2do de adolecentes
B24: =IF(C24="","",D24&F24&COUNTIFS($D$4:D24,D24,$F$4:F24,F24)) -> MS6 | C24: Clara Hernandez de Garcia | D24: M | E24: CG | F24: S | G24: SÍ | H24: SÍ | I24: 14848 | J24: =IF(C24="","",DATEDIF(I24,TODAY(),"Y")) -> 85 | K24: 3320749117 | L24: Demostenes 635 Col Libertad | M24: 43184 | N24: 18 casadas
B25: =IF(C25="","",D25&F25&COUNTIFS($D$4:D25,D25,$F$4:F25,F25)) -> HD4 | C25: Manjarrez Ayala Manuel | D25: H | E25: CG | F25: D | G25: SÍ | H25: SÍ | I25: 26167 | J25: =IF(C25="","",DATEDIF(I25,TODAY(),"Y")) -> 54 | K25: 3321892337 | L25: Emilio Rabaza 3923-13 col Jardines de San Francisco | M25: 04-ma-r18 | N25: 8vo casados
B26: =IF(C26="","",D26&F26&COUNTIFS($D$4:D26,D26,$F$4:F26,F26)) -> HD5 | C26: Calvillo Delgado Samuel | D26: H | E26: CM | F26: D | G26: SÍ | H26: SÍ | I26: 27033 | J26: =IF(C26="","",DATEDIF(I26,TODAY(),"Y")) -> 52 | K26: 3310197194 | L26: Turquia, 729, Col. Libertad | M26: 43198 | N26: Oaxaca de Juarez, P.E. Benjamin Chavez Joaquin
B27: =IF(C27="","",D27&F27&COUNTIFS($D$4:D27,D27,$F$4:F27,F27)) -> HMa2 | C27: García Aparicio Abisai | D27: H | E27: CC | F27: Ma | G27: SÍ | H27: SÍ | I27: 32944 | J27: =IF(C27="","",DATEDIF(I27,TODAY(),"Y")) -> 36 | K27: 3331815580 | L27: Presa Escondida, 3646, Col. Lagos de Oriente | M27: 43201 | N27: 2 de casados, David Pardo Rosales
B28: =IF(C28="","",D28&F28&COUNTIFS($D$4:D28,D28,$F$4:F28,F28)) -> HV3 | C28: Andrade Sanchez Pedro Joaquin | D28: H | E28: JU | F28: V | G28: SÍ | H28: SÍ | I28: 34217 | J28: =IF(C28="","",DATEDIF(I28,TODAY(),"Y")) -> 32 | L28: Demostenes, 520 | M28: 43201 | N28: Republica Dominicana, P.E. Ramiro Hernandez
B29: =IF(C29="","",D29&F29&COUNTIFS($D$4:D29,D29,$F$4:F29,F29)) -> MMa1 | C29: Serrano Garibay Beula Samir | D29: M | E29: JU | F29: Ma | G29: NO | H29: SÍ | I29: 37217 | J29: =IF(C29="","",DATEDIF(I29,TODAY(),"Y")) -> 24 | K29: 36080847 | L29: Jerusalen, 3550, Col. Hermosa Provincia | M29: 43193 | N29: sin carta
B30: =IF(C30="","",D30&F30&COUNTIFS($D$4:D30,D30,$F$4:F30,F30)) -> HMi1 | C30: Nava Larios Jocsan B. | D30: H | E30: JU | F30: Mi | G30: SÍ | H30: SÍ | I30: 38066 | J30: =IF(C30="","",DATEDIF(I30,TODAY(),"Y")) -> 22 | K30: 3318729482 | L30: Manuel Irigollen, 947, 2A. Secc. H P | M30: 43215 | N30: 2 adolescentes, Sergio Altamirano
B31: =IF(C31="","",D31&F31&COUNTIFS($D$4:D31,D31,$F$4:F31,F31)) -> HV4 | C31: Gongora Guardado Daniel | D31: H | E31: JU | F31: V | G31: SÍ | H31: SÍ | I31: 37975 | J31: =IF(C31="","",DATEDIF(I31,TODAY(),"Y")) -> 22 | L31: Jordan sur, 665, Hermosa Provincia | M31: 43203 | N31: 2 adolescentes, Sergio Altamirano
B32: =IF(C32="","",D32&F32&COUNTIFS($D$4:D32,D32,$F$4:F32,F32)) -> MD3 | C32: Castañeda Contreras Yolanda | D32: M | E32: JU | F32: D | G32: SÍ | H32: SÍ | I32: 34695 | J32: =IF(C32="","",DATEDIF(I32,TODAY(),"Y")) -> 31 | L32: Geografos, 680, Col. Lagos de Oriente | M32: 43177 | N32: 6 señoritas, Rosalisa Sosa
B33: =IF(C33="","",D33&F33&COUNTIFS($D$4:D33,D33,$F$4:F33,F33)) -> HS2 | C33: Herrera Rubio Angel Isaias | D33: H | E33: JU | F33: S | G33: SÍ | H33: SÍ | I33: 37932 | J33: =IF(C33="","",DATEDIF(I33,TODAY(),"Y")) -> 22 | K33: 3841171340 | L33: Genaro Garcia 3345, Miguel Hidalgo | M33: 43154 | N33: las vegas
B34: =IF(C34="","",D34&F34&COUNTIFS($D$4:D34,D34,$F$4:F34,F34)) -> MD4 | C34: Chavez Ubaldo Saudi | D34: M | E34: CM | F34: D | G34: SÍ | H34: SÍ | I34: 29849 | J34: =IF(C34="","",DATEDIF(I34,TODAY(),"Y")) -> 44 | K34: 3321715607 | L34: Pablo Valdez 4055, 2 seccion Hermosa Provincia | M34: 43131 | N34: 9 casadas, D. Yolanda Esparza
B35: =IF(C35="","",D35&F35&COUNTIFS($D$4:D35,D35,$F$4:F35,F35)) -> HD6 | C35: Segovia Manuel Antonio | D35: H | E35: SO | F35: D | G35: SÍ | H35: SÍ | I35: 28237 | J35: =IF(C35="","",DATEDIF(I35,TODAY(),"Y")) -> 49 | K35: no registro | M35: 43223 | N35: 2 solos, Abraham Vazquez Carcamo
B36: =IF(C36="","",D36&F36&COUNTIFS($D$4:D36,D36,$F$4:F36,F36)) -> HD7 | C36: Valencia Alegria Jonathan Abraham | D36: H | E36: JU | F36: D | G36: SÍ | H36: SÍ | I36: 38093 | J36: =IF(C36="","",DATEDIF(I36,TODAY(),"Y")) -> 22 | K36: 3331080997 | L36: Turquia, 639, Lagos de Oriente | M36: 43221 | N36: 2 adolescentes, Sergio Altamirano
B37: =IF(C37="","",D37&F37&COUNTIFS($D$4:D37,D37,$F$4:F37,F37)) -> MS7 | C37: Coronel Moreno Betsua | D37: M | E37: JU | F37: S | G37: SÍ | H37: SÍ | I37: 37395 | J37: =IF(C37="","",DATEDIF(I37,TODAY(),"Y")) -> 23 | K37: no registro | L37: Jerusalen 3488, Hermosa Provincia | M37: 43233 | N37: Teotlalco Veracruz, Enc. Alberto Coronel Morales
B38: =IF(C38="","",D38&F38&COUNTIFS($D$4:D38,D38,$F$4:F38,F38)) -> MJ2 | C38: Flores Moreno Ruth Areli | D38: M | E38: CC | F38: J | G38: SÍ | H38: SÍ | I38: 32379 | J38: =IF(C38="","",DATEDIF(I38,TODAY(),"Y")) -> 37 | K38: 3316330392 | L38: Canaan 3732, San Joaquin | M38: 43244 | N38: 6 casadas,
B39: =IF(C39="","",D39&F39&COUNTIFS($D$4:D39,D39,$F$4:F39,F39)) -> MS8 | C39: Guzmán Rodriguez Herziba Sabetai | D39: M | E39: JU | F39: S | G39: SÍ | H39: SÍ | I39: 38059 | J39: =IF(C39="","",DATEDIF(I39,TODAY(),"Y")) -> 22 | K39: no registro | L39: José Rosas Moreno 920, Miguel Hidalgo | M39: 43209
B40: =IF(C40="","",D40&F40&COUNTIFS($D$4:D40,D40,$F$4:F40,F40)) -> MS9 | C40: Mendoza Lara Sunem Areli | D40: M | E40: JU | F40: S | G40: SÍ | H40: SÍ | I40: 33898 | J40: =IF(C40="","",DATEDIF(I40,TODAY(),"Y")) -> 33 | L40: Jardines Japoneses | M40: 43269 | N40: Batallon
B41: =IF(C41="","",D41&F41&COUNTIFS($D$4:D41,D41,$F$4:F41,F41)) -> MMa2 | C41: Macias Alba Mara | D41: M | E41: CM | F41: Ma | G41: SÍ | H41: SÍ | J41: =IF(C41="","",DATEDIF(I41,TODAY(),"Y")) -> 126 | K41: 3312138088 | M41: 43257 | N41: 13 casadas D. Alma Zamora
...

Sheet Bajas
C1: ="Total: "&SUBTOTAL(3,$C$4:$C$39) -> Total: 36 | G1: =434-37+7 -> 404
A3: No. | B3: Llave | C3: N O M B R E | D3: G | E3: E.C. | F3: DIA | G3: CARTA | H3: REG. | I3: F. NAC. | J3: EDAD | K3: TEL. | L3: DIRECCION | M3: Mes de Baja | N3: OBS.
A4: =IF(D4="","",COUNTA($D$4:D4)) -> 1 | B4: =IF(C4="","",D4&F4&COUNTIFS($D$4:D4,D4,$F$4:F4,F4)) -> MB1 | C4: Jaramillo Zapata Ofir Esther | D4: M | E4: CM | F4: B | G4: SÍ | H4: SÍ | I4: 26724 | J4: =IF(C4="","",DATEDIF(I4,TODAY(),"Y")) -> 53 | K4: 3321305852 | L4: Etiopia, 808-A, Col. Cuahutemoc. | M4: octubre | N4: 13 casadas HP
A5: =IF(D5="","",COUNTA($D$4:D5)) -> 2 | B5: =IF(C5="","",D5&F5&COUNTIFS($D$4:D5,D5,$F$4:F5,F5)) -> MB2 | C5: Morales Santiago Elizabeth | D5: M | E5: JU | F5: B | G5: SÍ | J5: =IF(C5="","",DATEDIF(I5,TODAY(),"Y")) -> 126 | M5: octubre | N5: 3 de señoritas hp
A6: =IF(D6="","",COUNTA($D$4:D6)) -> 3 | B6: =IF(C6="","",D6&F6&COUNTIFS($D$4:D6,D6,$F$4:F6,F6)) -> HB1 | C6: Mendoza Rodríguez Salomón | D6: H | E6: CM | F6: B | G6: SÍ | H6: SÍ | I6: 26666 | J6: =IF(C6="","",DATEDIF(I6,TODAY(),"Y")) -> 53 | K6: 3334090315 | L6: Río Agua Naval, 1775, Urbi Quinta, Ton. | M6: octubre | N6: iglesia urbi
A7: =IF(D7="","",COUNTA($D$4:D7)) -> 4 | B7: =IF(C7="","",D7&F7&COUNTIFS($D$4:D7,D7,$F$4:F7,F7)) -> HB2 | C7: Calderón Cano Felipe | D7: H | E7: CG | F7: B | G7: SÍ | H7: SÍ | I7: 24143 | J7: =IF(C7="","",DATEDIF(I7,TODAY(),"Y")) -> 60 | K7: 3310730329 | L7: Gustavo Baz, 3728, Sn. Joaquin | M7: octubre | N7: DD
A8: =IF(D8="","",COUNTA($D$4:D8)) -> 5 | B8: =IF(C8="","",D8&F8&COUNTIFS($D$4:D8,D8,$F$4:F8,F8)) -> HB3 | C8: Barba Herrera Pedro | D8: H | E8: SO | F8: B | G8: SÍ | H8: SÍ | I8: 27422 | J8: =IF(C8="","",DATEDIF(I8,TODAY(),"Y")) -> 51 | K8: 3315513498 | L8: Canaan, 3491, Hermosa Provincia | M8: octubre | N8: puebla
A9: =IF(D9="","",COUNTA($D$4:D9)) -> 6 | B9: =IF(C9="","",D9&F9&COUNTIFS($D$4:D9,D9,$F$4:F9,F9)) -> HB4 | C9: Francisco López Job Isaac | D9: H | E9: JU | F9: B | G9: SÍ | H9: SÍ | I9: 36900 | J9: =IF(C9="","",DATEDIF(I9,TODAY(),"Y")) -> 25 | K9: 3314177458 | L9: SaMaría, 987, Hermosa Provincia | M9: octubre | N9: 1 jovenes
A10: =IF(D10="","",COUNTA($D$4:D10)) -> 7 | B10: =IF(C10="","",D10&F10&COUNTIFS($D$4:D10,D10,$F$4:F10,F10)) -> HB5 | C10: Pérez Martínez Abner | D10: H | E10: SO | F10: B | G10: SÍ | H10: SÍ | I10: 30430 | J10: =IF(C10="","",DATEDIF(I10,TODAY(),"Y")) -> 43 | K10: 3311257608 | L10: Arquimides, 640, Hermosa Provincia | M10: noviembre | N10: 4 casados ivan urrutia
A11: =IF(D11="","",COUNTA($D$4:D11)) -> 8 | B11: =IF(C11="","",D11&F11&COUNTIFS($D$4:D11,D11,$F$4:F11,F11)) -> HB6 | C11: Muñoz Onofre Daniel | D11: H | E11: CG | F11: B | G11: SÍ | H11: SÍ | I11: 12256 | J11: =IF(C11="","",DATEDIF(I11,TODAY(),"Y")) -> 92 | K11: 33330740 | L11: Esteban Alatorre,3376-11-A, Hermosa P | M11: noviembre | N11: durmio
A12: =IF(D12="","",COUNTA($D$4:D12)) -> 9 | B12: =IF(C12="","",D12&F12&COUNTIFS($D$4:D12,D12,$F$4:F12,F12)) -> MB3 | C12: Camacho Madrid Ma. Delia | D12: M | E12: SO | F12: B | G12: SÍ | H12: SÍ | I12: 20335 | J12: =IF(C12="","",DATEDIF(I12,TODAY(),"Y")) -> 70 | K12: 3511431661 | L12: SaMaría, 820, Hermosa Provincia | M12: noviembre | N12: michoacan por indicacion del Encargado
A13: =IF(D13="","",COUNTA($D$4:D13)) -> 10 | B13: =IF(C13="","",D13&F13&COUNTIFS($D$4:D13,D13,$F$4:F13,F13)) -> MB4 | C13: Mejía Estrada Elizabeth | D13: M | E13: CM | F13: B | G13: SÍ | H13: SÍ | I13: 28303 | J13: =IF(C13="","",DATEDIF(I13,TODAY(),"Y")) -> 48 | K13: 3312470335 | L13: Pablo Valdez, S/N Col. Libertad | M13: noviembre | N13: por indicacion del encargado
A14: =IF(D14="","",COUNTA($D$4:D14)) -> 11 | B14: =IF(C14="","",D14&F14&COUNTIFS($D$4:D14,D14,$F$4:F14,F14)) -> MB5 | C14: Silverio Flores Raquel | D14: M | E14: CM | F14: B | G14: SÍ | H14: SÍ | I14: 28008 | J14: =IF(C14="","",DATEDIF(I14,TODAY(),"Y")) -> 49 | K14: 3311766639 | L14: Educadores, 747, Lagos De Oriente. | M14: noviembre | N14: bethel
A15: =IF(D15="","",COUNTA($D$4:D15)) -> 12 | B15: =IF(C15="","",D15&F15&COUNTIFS($D$4:D15,D15,$F$4:F15,F15)) -> HB7 | C15: García Espinoza José Alberto | D15: H | E15: CM | F15: B | G15: SÍ | H15: SÍ | I15: 29242 | J15: =IF(C15="","",DATEDIF(I15,TODAY(),"Y")) -> 46 | K15: 3317048266 | L15: Educadores, 747, Lagos De Oriente | M15: noviembre | N15: bethel
A16: =IF(D16="","",COUNTA($D$4:D16)) -> 13 | B16: =IF(C16="","",D16&F16&COUNTIFS($D$4:D16,D16,$F$4:F16,F16)) -> HB8 | C16: Illescas Medina Gabriel | D16: H | E16: CM | F16: B | G16: SÍ | H16: SÍ | I16: 30805 | J16: =IF(C16="","",DATEDIF(I16,TODAY(),"Y")) -> 41 | K16: 3320581284 | L16: 2372-A Col. Libertad | M16: 43101 | N16: obra en Alemania
A17: =IF(D17="","",COUNTA($D$4:D17)) -> 14 | B17: =IF(C17="","",D17&F17&COUNTIFS($D$4:D17,D17,$F$4:F17,F17)) -> MB6 | C17: Coronado Hernandez Betsaida | D17: M | E17: CC | F17: B | G17: SÍ | H17: SÍ | I17: 31952 | J17: =IF(C17="","",DATEDIF(I17,TODAY(),"Y")) -> 38 | K17: 3314895765 | L17: Jerico, 797-A,Hermosa Provincia | M17: 43101 | N17: obra en Alemania
A18: =IF(D18="","",COUNTA($D$4:D18)) -> 15 | B18: =IF(C18="","",D18&F18&COUNTIFS($D$4:D18,D18,$F$4:F18,F18)) -> MB7 | C18: Orellana Perez Dalila | D18: M | E18: SO | F18: B | G18: SÍ | H18: SÍ | I18: 25420 | J18: =IF(C18="","",DATEDIF(I18,TODAY(),"Y")) -> 56 | L18: Demostenes, 971, Col. Libertad | M18: 43101 | N18: Guayabitos, Tlaquepaque
A19: =IF(D19="","",COUNTA($D$4:D19)) -> 16 | B19: =IF(C19="","",D19&F19&COUNTIFS($D$4:D19,D19,$F$4:F19,F19)) -> HB9 | C19: Dubon Jose Oscar | D19: H | E19: CG | F19: B | G19: SÍ | H19: NO | I19: 20552 | J19: =IF(C19="","",DATEDIF(I19,TODAY(),"Y")) -> 70 | L19: Telegrafistas, 173, Lagos de Oriente | M19: 42979
A20: =IF(D20="","",COUNTA($D$4:D20)) -> 17 | C20: Alegria Serrano Aram | D20: H | E20: JU | F20: B | G20: NO | H20: SÍ | I20: 37258 | J20: =IF(C20="","",DATEDIF(I20,TODAY(),"Y")) -> 24 | K20: 3331385646 | L20: Esbirna, 4007-A,Bethel | M20: 43132 | N20: Bethel
A21: =IF(D21="","",COUNTA($D$4:D21)) -> 18 | C21: Guerra Salgado Miguel | D21: H | E21: JU | F21: B | G21: SÍ | H21: SÍ | I21: 36865 | J21: =IF(C21="","",DATEDIF(I21,TODAY(),"Y")) -> 25 | K21: 3339057472 | L21: Getzemani, 3518, Hermosa Provincia | M21: 43132 | N21: 1er Jovenes
A22: =IF(D22="","",COUNTA($D$4:D22)) -> 19 | C22: Ferrusca García Irene | D22: M | E22: SO | F22: B | G22: SÍ | H22: SÍ | I22: 31226 | J22: =IF(C22="","",DATEDIF(I22,TODAY(),"Y")) -> 40 | K22: 3317810760 | L22: Arquimides, 780, Hermosa Provincia | M22: 43132 | N22: P.E Adan armenta col san cayetano pachuca Hidalgo
A23: =IF(D23="","",COUNTA($D$4:D23)) -> 20 | C23: Vázquez Calvillo Uziel | D23: H | E23: JU | F23: B | G23: SÍ | H23: SÍ | I23: 37138 | J23: =IF(C23="","",DATEDIF(I23,TODAY(),"Y")) -> 24 | K23: 55.7063.5632 | L23: Cirujanos 533, Lagos De Oriente | M23: 43132 | N23: D D
A24: =IF(D24="","",COUNTA($D$4:D24)) -> 21 | C24: López López Argenis | D24: H | E24: CC | F24: B | G24: SÍ | H24: SÍ | I24: 34162 | J24: =IF(C24="","",DATEDIF(I24,TODAY(),"Y")) -> 32 | K24: 3320681505 | L24: Nazaret 635, Lagos De Oriente | M24: 43132 | N24: D D
A25: =IF(D25="","",COUNTA($D$4:D25)) -> 22 | C25: Arenas González Abdiel | D25: H | E25: JU | F25: B | G25: SÍ | H25: SÍ | I25: 36515 | J25: =IF(C25="","",DATEDIF(I25,TODAY(),"Y")) -> 26 | K25: 36041152 | L25: Cirujanos, 679, Lagos De Oriente. | M25: 43132 | N25: D D
A26: =IF(D26="","",COUNTA($D$4:D26)) -> 23 | C26: Hernández Parra Brisia Paola | D26: M | E26: CM | F26: B | G26: SÍ | H26: SÍ | I26: 30977 | J26: =IF(C26="","",DATEDIF(I26,TODAY(),"Y")) -> 41 | K26: 3331817950 | L26: Presa Valsequillo, 776, Col. San Joaquin | M26: 43132 | N26: D D
A27: =IF(D27="","",COUNTA($D$4:D27)) -> 24 | C27: Flores Victoria | D27: M | E27: SO | F27: B | G27: SÍ | H27: SÍ | I27: 17956 | J27: =IF(C27="","",DATEDIF(I27,TODAY(),"Y")) -> 77 | K27: 3310051031 | L27: Canaan 3642, San Joaquin | M27: 43132 | N27: El Salvador
A28: =IF(D28="","",COUNTA($D$4:D28)) -> 25 | C28: Silva Morales Martha Elva | D28: M | E28: SO | F28: Mi | G28: SÍ | H28: SÍ | I28: 17644 | J28: =IF(C28="","",DATEDIF(I28,TODAY(),"Y")) -> 78 | K28: 36980023 | L28: Canaan,3508,Hermosa Provincia | M28: 43132 | N28: tapachula chiapas
A29: =IF(D29="","",COUNTA($D$4:D29)) -> 26 | C29: Delgado Blanco Mara | D29: M | E29: CG | F29: B | G29: SÍ | H29: SÍ | I29: 20606 | J29: =IF(C29="","",DATEDIF(I29,TODAY(),"Y")) -> 69 | K29: 3317917891 | L29: Gustavo Baz,3411, Miguel Hidalgo | M29: 43132 | N29: D D
A30: =IF(D30="","",COUNTA($D$4:D30)) -> 27 | C30: Ramires Mejia Figlodervina | D30: M | E30: CG | F30: B | G30: SÍ | H30: NO | I30: 19874 | J30: =IF(C30="","",DATEDIF(I30,TODAY(),"Y")) -> 71 | L30: Telegrafistas, 173, Lagos de Oriente | M30: 43132 | N30: D D
A31: =IF(D31="","",COUNTA($D$4:D31)) -> 28 | C31: Aguilera Salas Adalia Quiriabeth | D31: M | E31: CC | F31: B | G31: SÍ | H31: SÍ | I31: 33129 | J31: =IF(C31="","",DATEDIF(I31,TODAY(),"Y")) -> 35 | K31: 3313833507 | L31: Jardin Botanico,3490,Lagos de Oriente | M31: 43132 | N31: D D
A32: =IF(D32="","",COUNTA($D$4:D32)) -> 29 | C32: Martínez Robles Amsi Elizabeth | D32: M | E32: JU | F32: B | G32: SÍ | H32: SÍ | I32: 35893 | J32: =IF(C32="","",DATEDIF(I32,TODAY(),"Y")) -> 28 | K32: 3321782248 | L32: Canaan,, 3465, Hermosa Provincia | M32: 43132 | N32: Gpo señoritas
A33: =IF(D33="","",COUNTA($D$4:D33)) -> 30 | C33: Ávalos Nuila Sayri | D33: M | E33: JU | F33: B | G33: SÍ | H33: SÍ | I33: 36740 | J33: =IF(C33="","",DATEDIF(I33,TODAY(),"Y")) -> 25 | K33: 3315701826 | L33: Esteban Alatorre, 3331, Hermosa Provincia | M33: 43132 | N33: Canada
A34: =IF(D34="","",COUNTA($D$4:D34)) -> 31 | C34: Muñoz Sánchez Luz Elizabeth | D34: M | E34: JU | F34: B | G34: SÍ | H34: SÍ | I34: 34370 | J34: =IF(C34="","",DATEDIF(I34,TODAY(),"Y")) -> 32 | K34: 3311491425 | L34: Presa Laurel, 146, Tetlan | M34: 43132 | N34: Gpo señoritas
A35: =IF(D35="","",COUNTA($D$4:D35)) -> 32 | C35: Orizaba Ramírez Abigail | D35: M | E35: JU | F35: B | G35: SÍ | H35: SÍ | I35: 35073 | J35: =IF(C35="","",DATEDIF(I35,TODAY(),"Y")) -> 30 | K35: 3313078144 | L35: Privada De Belen, 99, Hermosa Provincia | M35: 43132 | N35: Gpo señoritas
A36: =IF(D36="","",COUNTA($D$4:D36)) -> 33 | C36: Trujillo Hernández Betsua | D36: M | E36: JU | F36: B | G36: SÍ | H36: SÍ | I36: 36127 | J36: =IF(C36="","",DATEDIF(I36,TODAY(),"Y")) -> 27 | K36: 3320919161 | L36: Real Del Mezquites, ?, Camichines Tonala | M36: 43132 | N36: D D
A37: =IF(D37="","",COUNTA($D$4:D37)) -> 34 | C37: Trujillo Hernández Libni | D37: M | E37: CC | F37: B | G37: SÍ | I37: 32896 | J37: =IF(C37="","",DATEDIF(I37,TODAY(),"Y")) -> 36 | K37: 3319422219 | L37: Jordan 770-A col hermosa provincia | M37: 43132 | N37: D D
A38: =IF(D38="","",COUNTA($D$4:D38)) -> 35 | B38: =IF(C38="","",D38&F38&COUNTIFS($D$4:D38,D38,$F$4:F38,F38)) -> HMi1 | C38: Núñez Larios Daniel Benjamín | D38: H | E38: JU | F38: Mi | G38: SÍ | H38: SÍ | I38: 35535 | J38: =IF(C38="","",DATEDIF(I38,TODAY(),"Y")) -> 29 | K38: 3317927906 | L38: Jordan, 655, Hermosa Provincia | M38: 43160 | N38: 3er jovenes
A39: =IF(D39="","",COUNTA($D$4:D39)) -> 36 | B39: =IF(C39="","",D39&F39&COUNTIFS($D$4:D39,D39,$F$4:F39,F39)) -> HS1 | C39: Vázquez Vargas Jesse Kibsaim | D39: H | E39: JU | F39: S | G39: SÍ | H39: SÍ | I39: 36666 | J39: =IF(C39="","",DATEDIF(I39,TODAY(),"Y")) -> 25 | K39: 3335592703 | L39: Telegrafistas, 3377, Lagos De Oriente | M39: 43160
A40: =IF(D40="","",COUNTA($D$4:D40)) -> 37 | B40: =IF(C40="","",D40&F40&COUNTIFS($D$4:D40,D40,$F$4:F40,F40)) -> MMi2 | C40: Núñez Larios Salma Betsabé | D40: M | E40: JU | F40: Mi | G40: SÍ | H40: SÍ | I40: 35030 | J40: =IF(C40="","",DATEDIF(I40,TODAY(),"Y")) -> 30 | K40: 3312614134 | L40: Jerusalen, 3449, Hermosa Provincia | M40: marrzo-18 | N40: 3er señoritas
A41: =IF(D41="","",COUNTA($D$4:D41)) -> 38 | B41: =IF(C41="","",D41&F41&COUNTIFS($D$4:D41,D41,$F$4:F41,F41)) -> HS2 | C41: Carrillo Herrera Jachin | D41: H | E41: JU | F41: S | G41: SÍ | H41: SÍ | I41: 36673 | J41: =IF(C41="","",DATEDIF(I41,TODAY(),"Y")) -> 25 | K41: 3311746121 | L41: Nazaret, 687, Hermosa Provincia | M41: 43160 | N41: 2do jovenes
...

Sheet Revisión
C1: nombres | D1: Columna1 | E1: E.C | F1: Dia | G1: Columna2 | H1: Columna3 | I1: Columna4 | J1: EDAD | K1: TEL | L1: DIRECCION | M1: Razones que se conocen en día de guardia
B2: =IF(C2="","",D2&F2&COUNTIFS($D2:D$3,D2,$F2:F$3,F2)) -> MJ1 | C2: Ramírez García Mayra Nayeli | D2: M | E2: JU | F2: J | G2: SÍ | H2: SÍ | I2: 36175 | J2: =IF(C2="","",DATEDIF(I2,TODAY(),"Y")) -> 27 | K2: 3334484036 | L2: Educadores 3304, Lagos de Oriente | M2: Cambio de grupo
B3: =IF(C3="","",D3&F3&COUNTIFS($D3:D$3,D3,$F3:F$3,F3)) -> HL1 | C3: González Constantino R. Leonel | D3: H | E3: CM | F3: L | G3: SÍ | H3: SÍ | I3: 28879 | J3: =IF(C3="","",DATEDIF(I3,TODAY(),"Y")) -> 47 | K3: 3338475744 | L3: Jardin Botanico, 3340, Lagos De Oriente | M3: Se desconoce la razon de su ausencia
B4: =IF(C4="","",D4&F4&COUNTIFS($D4:D$3,D4,$F4:F$3,F4)) -> HL2 | C4: Guadarrama Arce Abner Abisai | D4: H | E4: JU | F4: L | G4: SÍ | H4: SÍ | I4: 37653 | J4: =IF(C4="","",DATEDIF(I4,TODAY(),"Y")) -> 23 | K4: 3313247563 | L4: Telegrafistas 3490, Lagos de Oriente. | M4: más de tres meses faltado
B5: =IF(C5="","",D5&F5&COUNTIFS($D5:D$3,D5,$F5:F$3,F5)) -> HL3 | C5: Pelayo Díaz Policarpo | D5: H | E5: SO | F5: L | G5: SÍ | H5: SÍ | I5: 12810 | J5: =IF(C5="","",DATEDIF(I5,TODAY(),"Y")) -> 91 | K5: SIN | L5: Turquia, 707, Col. Libertad | M5: comportamiento impropio de un obrero, no se sujeta al responsable
B6: =IF(C6="","",D6&F6&COUNTIFS($D6:D$3,D6,$F6:F$3,F6)) -> MS1 | C6: Serrano Mora Ishua | D6: M | E6: CM | F6: S | G6: SÍ | H6: NO | I6: 30585 | J6: =IF(C6="","",DATEDIF(I6,TODAY(),"Y")) -> 42 | K6: 3312987565 | L6: Esteban A La Torre, 3377, Hermosa Provincia | M6: cambio a grupo de casadas
B7: =IF(C7="","",D7&F7&COUNTIFS($D7:D$3,D7,$F7:F$3,F7)) -> HL4 | C7: Olivares Rodríguez Edgar Joram | D7: H | E7: JU | F7: L | G7: SÍ | H7: SÍ | I7: 36502 | J7: =IF(C7="","",DATEDIF(I7,TODAY(),"Y")) -> 26 | K7: 3339705399 | L7: Jerusalen, 3382, Hermosa Provincia | M7: mas de tres meses faltado
B8: =IF(C8="","",D8&F8&COUNTIFS($D8:D$3,D8,$F8:F$3,F8)) -> HL5 | C8: Ruvalcaba Hernández Omar Jesús | D8: H | E8: SO | F8: L | G8: SÍ | H8: SÍ | I8: 30926 | J8: =IF(C8="","",DATEDIF(I8,TODAY(),"Y")) -> 41 | K8: 3319901048 | L8: Felix Bernardeli, 138, Int. 11, Sn Andres. | M8: poca asistencia a la obra
C9: Cabrera Comunidad Raul | D9: H | E9: JU | F9: D | G9: SÍ | H9: SÍ | I9: 35210 | J9: 22 | K9: 3334973578 | L9: Presa Osorio | M9: 9 meses de ausentismo
C10: Calvillo Delgado Samuel | D10: H | E10: CM | F10: D | G10: SÍ | H10: SÍ | I10: 27033 | J10: 45 | K10: 3310197194 | L10: Turquia, 729, Col. Libertad | M10: 5 a 6 meses de residencia
C11: Cortez Aguayo Mario | D11: H | E11: CM | F11: D | G11: SÍ | H11: SÍ | I11: 27110 | J11: 44 | K11: 33.1230.6202 | L11: Presa Sanalona 867, San Joaquín | M11: 1 año de ausentismo asunto laboral
C12: Estrada Martin Benjamín | D12: H | E12: JU | F12: D | G12: SÍ | H12: SÍ | I12: 37904 | J12: 15 | K12: 2781130373 | L12: Jardines Botanicos, Lagos de Oriente | M12: 1 mes de ausentismo
C13: Flores Valencia Fines Edrei | D13: H | E13: JU | F13: D | G13: NO | H13: SÍ | I13: 37816 | J13: 15 | K13: 3331191945 | L13: Josefa Ortiz de Dominguez, | M13: no se presenta
C14: Ipiña Del Río Adiel Silem | D14: H | E14: JU | F14: D | G14: SÍ | H14: SÍ | I14: 35902 | J14: 20 | K14: 3313667413 | L14: Turquia, 729, Col. Lagos De Oriente. | M14: 8 a 9 meses ausentismo esta en el coro de jovenes
C15: Luna Pérez Antonio | D15: H | E15: CG | F15: D | G15: SÍ | H15: SÍ | I15: 24271 | J15: 52 | K15: 3312665737 | L15: Belen, 3433, Hermosa Provincia | M15: inconstancia por asunto laboral
C16: Pedroza Ascencio Leonardo Daniel | D16: H | E16: CC | F16: D | G16: SÍ | H16: SÍ | I16: 31086 | J16: 33 | K16: 32223065534 | L16: Nazareth, 686, Lagos De Oriente | M16: cambio de residencia por asunto laboral
C17: Ramires Leon Marcos | D17: H | E17: CM | F17: D | G17: SÍ | H17: SÍ | J17: 119 | K17: 3310807887 | M17: 3 a 4 meses de ausentismo por asunto laboral
C18: Rivas Martinez Hugo Cesar | D18: H | E18: JU | F18: D | G18: SÍ | H18: SÍ | I18: 34451 | J18: 24 | K18: 4271365698 | L18: Presa Sanalona 858, Hermosa Provincia | M18: 3 a 4 meses de ausentismo, cambio de residencia por asunto laboral
C19: Rodríguez Islas Héctor | D19: H | E19: CG | F19: D | G19: SÍ | H19: SÍ | I19: 24048 | J19: 53 | K19: 3310094665 | L19: Presa Sanalona, 825, Hermosa Provincia | M19: 2 años de ausentismo
C20: Von-Arx Bai Mario Hans | D20: H | E20: SO | F20: D | G20: SÍ | H20: SÍ | I20: 18112 | J20: 69 | K20: 3314393948 | L20: Pablo Valdez 3247, int.3,Cuahutemoc | M20: 10 a 11 meses de ausentismo por razones de salud

Sheet lista por edad
A1: 2° Adolescentes | F1: 2° Adolescentes
A2: N O M B R E | B2: EDAD | C2: TEL. | D2: DIRECCION | F2: N O M B R E | G2: EDAD | H2: TEL. | I2: DIRECCION
A3: Bernal Carillo Yair | B3: 15 | C3: 3328079212 | D3: Telegrafistas 3492, Hermosa Provinica | F3: Botello Vázquez Jabnia Nahomi | G3: 15 | I3: Santo Tomas 3096, Cuahutemoc
A4: Berumen Rosales Josue | B4: 15 | C4: 3334423388 | D4: Escalon 627, Lagos de Oriente | F4: Grajales Santos Yebzi Alejandra | G4: 14 | H4: 3325214476 | I4: Pablo Valdez y Presa Tacotan 844A, San Joaquin
A5: Castillo Lopez Absalon Abisai | B5: 14 | C5: 3310147850 | D5: Vicente Daza 1014, Lomas del Gallo | F5: Hernández Sánchez Priscila | G5: 15 | I5: Esteban Alatorre 33770,9B. Hermosa Provincia
A6: Cervantes Chavero Asael | B6: 15 | D6: Educadores 3329, Lagos de Oriente | F6: Libonatti Valdivia Abby Gethsemani | G6: 15 | H6: 5562173928 | I6: Gustavo Baz 3725, 2da sección HP
A7: Cordero García Saharaim | B7: 15 | D7: Fisicos 3465, Lagos de Oriente | F7: Trujillo Muñoz Suni Elizabeth | G7: 14 | H7: 36056403 | I7: Presa Laurel 146, Tetlan
A8: De la Cruz Valle Aziel | B8: 15 | C8: 3337228328 | D8: Arquimides 662, Hermosa Provincia
A9: Gomez Miramontes Jazak | B9: 15 | D9: Jerusalen 3306, Hermosa Provincia | F9: 1° Señoritas
A10: Gongora Guardado Jossiel | B10: 15 | C10: 3322197141 | D10: Jordan Sur 673, Hermosa Provincia | F10: N O M B R E | G10: EDAD | H10: TEL. | I10: DIRECCION
A11: Gutierrez Rodas Geser Heliel | B11: 14 | F11: Acuña Silverio Yenni Samai | G11: 17 | H11: 3325006442 | I11: Esteban Alatorre 3349, Hermosa Provincia
A12: Hernández Larios Pablo Benjamín | B12: 14 | D12: Nazareth 743, Hermosa Provincia | F12: Chavez Rebeca | G12: 16 | I12: Andador Guillermo Jimenez, Arrayanes
A13: Morales Solares Eliezer Mizraim | B13: 15 | C13: 3318412959 | D13: Jardines Japoneses 3571, Lagos de Oriente | F13: Colin Mora Adi Sinai | G13: 16 | H13: 3328329014 | I13: Hacienda Bellavista 3576, Heliodoro Hernández Loza
A14: Olachea Guzmán Omar Hidai | B14: 14 | C14: 3336438343 | D14: Etiopía 755, Libertad | F14: Luevanos Clemente Danna Nahomi | G14: 17 | H14: 3315550055 | I14: Jardines Japoneses 3311, Lagos de Oriente
A15: Orozco Guerra Zimri Adoraim | B15: 15 | C15: 3323218870 | D15: Getsemani 3618, Hermosa Provincia | F15: Muñoz Guzmán Salma Nohemi | G15: 16 | H15: 3313122738 | I15: Credito 4088, Benito Juarez
A16: Ramos Hernández Zair Alonso | B16: 14 | C16: 3330289797 | D16: Samaria 934, Hermosa Provincia | F16: Ochoa Bernal Siurabet Alejandra | G16: 17 | H16: 36085766 | I16: Malecon 1015, Lomas del Gallo
A17: Reyes Baldovinos Zabdiel Isai | B17: 15 | C17: 3921310443 | D17: Presa La Escondida, San Joaquín | F17: Ortega Sosa Sabetai | G17: 16 | H17: 3310931478 | I17: Pablo Moreno, 911, Hermosa Provincia
A18: Rodríguez Cardona Yeycob Yandel | B18: 15 | D18: Samaria 823, Hermosa Provincia | F18: Pardo Vazquez Java Ismerai | G18: 16 | H18: 3319246889 | I18: Presa Oviachic 76
A19: Rojas Cano Alan Adoraim | B19: 14 | D19: Samaria 935, Hermosa Provincia | F19: Pierrez Carrillo Dana Yahani | G19: 17 | I19: Presa Santa Rosa 587-A, Lagos de Oriente
A20: Serrano Navarro Samlai Jeriel | B20: 15 | D20: Esteban Alatorre 3536, Hermosa Provincia | F20: Valencia Alegría Elia Esbahi | G20: 17 | I20: Turquía 639, Lagos de Oriente
A21: Valencia Alegria Bany Edrei | B21: 15 | D21: Turquia 639, Lagos de Oriente
A22: Virgen Romero Itiel Kimsaim | B22: 15 | C22: 3334936229 | D22: Getsemani 3552, Hermosa Provincia | F22: 2° Señoritas
F23: N O M B R E | G23: EDAD | H23: TEL. | I23: DIRECCION
A24: 1° Jóvenes | F24: Acevedo Vega Samla Jaanai | G24: 19 | H24: 3316716256 | I24: Esteban Alatorre,3317,Hermosa Provincia
A25: N O M B R E | B25: EDAD | C25: TEL. | D25: DIRECCION | F25: Cortez Meza Merari Sinai | G25: 18 | H25: 3329679261 | I25: Nazareth 615, Hermosa Provincia
